Traceback (most recent call last):
  File "C:\Users\triad\AppData\Local\Programs\Python\Python39\lib\site-packages\jupyter_core\utils\__init__.py", line 154, in wrapped
    asyncio.get_running_loop()
RuntimeError: no running event loop

During handling of the above exception, another exception occurred:

Traceback (most recent call last):
  File "C:\Users\triad\AppData\Local\Programs\Python\Python39\lib\site-packages\jupyter_cache\executors\utils.py", line 58, in single_nb_execution
    executenb(
  File "C:\Users\triad\AppData\Local\Programs\Python\Python39\lib\site-packages\nbclient\client.py", line 1319, in execute
    return NotebookClient(nb=nb, resources=resources, km=km, **kwargs).execute()
  File "C:\Users\triad\AppData\Local\Programs\Python\Python39\lib\site-packages\jupyter_core\utils\__init__.py", line 158, in wrapped
    return loop.run_until_complete(inner)
  File "C:\Users\triad\AppData\Local\Programs\Python\Python39\lib\asyncio\base_events.py", line 647, in run_until_complete
    return future.result()
  File "C:\Users\triad\AppData\Local\Programs\Python\Python39\lib\site-packages\nbclient\client.py", line 709, in async_execute
    await self.async_execute_cell(
  File "C:\Users\triad\AppData\Local\Programs\Python\Python39\lib\site-packages\nbclient\client.py", line 1062, in async_execute_cell
    await self._check_raise_for_error(cell, cell_index, exec_reply)
  File "C:\Users\triad\AppData\Local\Programs\Python\Python39\lib\site-packages\nbclient\client.py", line 918, in _check_raise_for_error
    raise CellExecutionError.from_cell_and_msg(cell, exec_reply_content)
nbclient.exceptions.CellExecutionError: An error occurred while executing the following cell:
------------------

class_counts = y.value_counts()

plt.figure(figsize=(8,5))
plt.bar(class_counts.index, class_counts.values)
plt.title("Distribusi Jumlah Sampel per Kelas (Sebelum Penyeimbangan)")
plt.xlabel("Kelas")
plt.ylabel("Jumlah Sampel")
plt.xticks(rotation=45)
plt.show()

------------------


[1;31m---------------------------------------------------------------------------[0m
[1;31mNameError[0m                                 Traceback (most recent call last)
Cell [1;32mIn[5], line 1[0m
[1;32m----> 1[0m class_counts [38;5;241m=[39m [43my[49m[38;5;241m.[39mvalue_counts()
[0;32m      3[0m plt[38;5;241m.[39mfigure(figsize[38;5;241m=[39m([38;5;241m8[39m,[38;5;241m5[39m))
[0;32m      4[0m plt[38;5;241m.[39mbar(class_counts[38;5;241m.[39mindex, class_counts[38;5;241m.[39mvalues)

[1;31mNameError[0m: name 'y' is not defined

