Traceback (most recent call last):
  File "C:\Users\triad\AppData\Local\Programs\Python\Python39\lib\site-packages\jupyter_core\utils\__init__.py", line 154, in wrapped
    asyncio.get_running_loop()
RuntimeError: no running event loop

During handling of the above exception, another exception occurred:

Traceback (most recent call last):
  File "C:\Users\triad\AppData\Local\Programs\Python\Python39\lib\site-packages\jupyter_cache\executors\utils.py", line 58, in single_nb_execution
    executenb(
  File "C:\Users\triad\AppData\Local\Programs\Python\Python39\lib\site-packages\nbclient\client.py", line 1319, in execute
    return NotebookClient(nb=nb, resources=resources, km=km, **kwargs).execute()
  File "C:\Users\triad\AppData\Local\Programs\Python\Python39\lib\site-packages\jupyter_core\utils\__init__.py", line 158, in wrapped
    return loop.run_until_complete(inner)
  File "C:\Users\triad\AppData\Local\Programs\Python\Python39\lib\asyncio\base_events.py", line 647, in run_until_complete
    return future.result()
  File "C:\Users\triad\AppData\Local\Programs\Python\Python39\lib\site-packages\nbclient\client.py", line 709, in async_execute
    await self.async_execute_cell(
  File "C:\Users\triad\AppData\Local\Programs\Python\Python39\lib\site-packages\nbclient\client.py", line 1062, in async_execute_cell
    await self._check_raise_for_error(cell, cell_index, exec_reply)
  File "C:\Users\triad\AppData\Local\Programs\Python\Python39\lib\site-packages\nbclient\client.py", line 918, in _check_raise_for_error
    raise CellExecutionError.from_cell_and_msg(cell, exec_reply_content)
nbclient.exceptions.CellExecutionError: An error occurred while executing the following cell:
------------------
le = LabelEncoder()
y_enc = le.fit_transform(df["localization_class"])
print(pd.Series(y_enc).value_counts())
------------------


[1;31m---------------------------------------------------------------------------[0m
[1;31mKeyError[0m                                  Traceback (most recent call last)
File [1;32m~\AppData\Local\Programs\Python\Python39\lib\site-packages\pandas\core\indexes\base.py:3812[0m, in [0;36mIndex.get_loc[1;34m(self, key)[0m
[0;32m   3811[0m [38;5;28;01mtry[39;00m:
[1;32m-> 3812[0m     [38;5;28;01mreturn[39;00m [38;5;28;43mself[39;49m[38;5;241;43m.[39;49m[43m_engine[49m[38;5;241;43m.[39;49m[43mget_loc[49m[43m([49m[43mcasted_key[49m[43m)[49m
[0;32m   3813[0m [38;5;28;01mexcept[39;00m [38;5;167;01mKeyError[39;00m [38;5;28;01mas[39;00m err:

File [1;32mpandas/_libs/index.pyx:167[0m, in [0;36mpandas._libs.index.IndexEngine.get_loc[1;34m()[0m

File [1;32mpandas/_libs/index.pyx:196[0m, in [0;36mpandas._libs.index.IndexEngine.get_loc[1;34m()[0m

File [1;32mpandas/_libs/hashtable_class_helper.pxi:7088[0m, in [0;36mpandas._libs.hashtable.PyObjectHashTable.get_item[1;34m()[0m

File [1;32mpandas/_libs/hashtable_class_helper.pxi:7096[0m, in [0;36mpandas._libs.hashtable.PyObjectHashTable.get_item[1;34m()[0m

[1;31mKeyError[0m: 'localization_class'

The above exception was the direct cause of the following exception:

[1;31mKeyError[0m                                  Traceback (most recent call last)
Cell [1;32mIn[5], line 2[0m
[0;32m      1[0m le [38;5;241m=[39m LabelEncoder()
[1;32m----> 2[0m y_enc [38;5;241m=[39m le[38;5;241m.[39mfit_transform([43mdf[49m[43m[[49m[38;5;124;43m"[39;49m[38;5;124;43mlocalization_class[39;49m[38;5;124;43m"[39;49m[43m][49m)
[0;32m      3[0m [38;5;28mprint[39m(pd[38;5;241m.[39mSeries(y_enc)[38;5;241m.[39mvalue_counts())

File [1;32m~\AppData\Local\Programs\Python\Python39\lib\site-packages\pandas\core\frame.py:4107[0m, in [0;36mDataFrame.__getitem__[1;34m(self, key)[0m
[0;32m   4105[0m [38;5;28;01mif[39;00m [38;5;28mself[39m[38;5;241m.[39mcolumns[38;5;241m.[39mnlevels [38;5;241m>[39m [38;5;241m1[39m:
[0;32m   4106[0m     [38;5;28;01mreturn[39;00m [38;5;28mself[39m[38;5;241m.[39m_getitem_multilevel(key)
[1;32m-> 4107[0m indexer [38;5;241m=[39m [38;5;28;43mself[39;49m[38;5;241;43m.[39;49m[43mcolumns[49m[38;5;241;43m.[39;49m[43mget_loc[49m[43m([49m[43mkey[49m[43m)[49m
[0;32m   4108[0m [38;5;28;01mif[39;00m is_integer(indexer):
[0;32m   4109[0m     indexer [38;5;241m=[39m [indexer]

File [1;32m~\AppData\Local\Programs\Python\Python39\lib\site-packages\pandas\core\indexes\base.py:3819[0m, in [0;36mIndex.get_loc[1;34m(self, key)[0m
[0;32m   3814[0m     [38;5;28;01mif[39;00m [38;5;28misinstance[39m(casted_key, [38;5;28mslice[39m) [38;5;129;01mor[39;00m (
[0;32m   3815[0m         [38;5;28misinstance[39m(casted_key, abc[38;5;241m.[39mIterable)
[0;32m   3816[0m         [38;5;129;01mand[39;00m [38;5;28many[39m([38;5;28misinstance[39m(x, [38;5;28mslice[39m) [38;5;28;01mfor[39;00m x [38;5;129;01min[39;00m casted_key)
[0;32m   3817[0m     ):
[0;32m   3818[0m         [38;5;28;01mraise[39;00m InvalidIndexError(key)
[1;32m-> 3819[0m     [38;5;28;01mraise[39;00m [38;5;167;01mKeyError[39;00m(key) [38;5;28;01mfrom[39;00m[38;5;250m [39m[38;5;21;01merr[39;00m
[0;32m   3820[0m [38;5;28;01mexcept[39;00m [38;5;167;01mTypeError[39;00m:
[0;32m   3821[0m     [38;5;66;03m# If we have a listlike key, _check_indexing_error will raise[39;00m
[0;32m   3822[0m     [38;5;66;03m#  InvalidIndexError. Otherwise we fall through and re-raise[39;00m
[0;32m   3823[0m     [38;5;66;03m#  the TypeError.[39;00m
[0;32m   3824[0m     [38;5;28mself[39m[38;5;241m.[39m_check_indexing_error(key)

[1;31mKeyError[0m: 'localization_class'

